Workbook

Sheet Note
A1: The only data that needs to be filled in is on Input and Orientations tab.
A2: Just enter data in the user input boxes (15 boxes total, just one side of the pairwise comparison), all other tabs will be auto calculated
A3: The Rankings tab shows the scores. Scroll down.
A4: The input boxes are the colored cells below the diagonal of the User Input block (A4, A5:B5, A6:C6, A7:D7, A8:E8). Sample values are pre-filled; overwrite them with your own judgments.
A5: Each entry must be strictly between 0 and 100 (an entry of exactly 0 or 100 causes a divide-by-zero in the ratios).

Sheet Permutations
A1: Perm # | B1: Column1 | C1: Column2 | D1: Column3 | E1: Column4 | F1: Column5 | G1: Column6 | H1: Perm Copy (just for easing manual copy and paste)
A2: 1 | B2: 1 | C2: 2 | D2: 3 | E2: 4 | F2: 5 | G2: 6 | I2: p1 - i1:i2 | J2: p2 - i2:i3 | K2: p3 - i3:i4 | L2: p4 - i4:i5 | M2: p15 - i5:i6
A3: 2 | B3: 1 | C3: 2 | D3: 3 | E3: 4 | F3: 6 | G3: 5 | H3: 2 | I3: p1 - i1:i2 | J3: p2 - i2:i3 | K3: p3 - i3:i4 | L3: p14 - i4:i6 | M3: p151 - i6:i5
A4: 3 | B4: 1 | C4: 2 | D4: 3 | E4: 5 | F4: 4 | G4: 6 | H4: 3 | I4: p1 - i1:i2 | J4: p2 - i2:i3 | K4: p6 - i3:i5 | L4: p41 - i5:i4 | M4: p14 - i4:i6
A5: 4 | B5: 1 | C5: 2 | D5: 3 | E5: 5 | F5: 6 | G5: 4 | H5: 4 | I5: p1 - i1:i2 | J5: p2 - i2:i3 | K5: p6 - i3:i5 | L5: p15 - i5:i6 | M5: p141 - i6:i4
A6: 5 | B6: 1 | C6: 2 | D6: 3 | E6: 6 | F6: 4 | G6: 5 | H6: 5 | I6: p1 - i1:i2 | J6: p2 - i2:i3 | K6: p13 - i3:i6 | L6: p141 - i6:i4 | M6: p4 - i4:i5
A7: 6 | B7: 1 | C7: 2 | D7: 3 | E7: 6 | F7: 5 | G7: 4 | H7: 6 | I7: p1 - i1:i2 | J7: p2 - i2:i3 | K7: p13 - i3:i6 | L7: p151 - i6:i5 | M7: p41 - i5:i4
A8: 7 | B8: 1 | C8: 2 | D8: 4 | E8: 3 | F8: 5 | G8: 6 | H8: 7 | I8: p1 - i1:i2 | J8: p5 - i2:i4 | K8: p31 - i4:i3 | L8: p6 - i3:i5 | M8: p15 - i5:i6
A9: 8 | B9: 1 | C9: 2 | D9: 4 | E9: 3 | F9: 6 | G9: 5 | H9: 8 | I9: p1 - i1:i2 | J9: p5 - i2:i4 | K9: p31 - i4:i3 | L9: p13 - i3:i6 | M9: p151 - i6:i5
A10: 9 | B10: 1 | C10: 2 | D10: 4 | E10: 5 | F10: 3 | G10: 6 | H10: 9 | I10: p1 - i1:i2 | J10: p5 - i2:i4 | K10: p4 - i4:i5 | L10: p61 - i5:i3 | M10: p13 - i3:i6
A11: 10 | B11: 1 | C11: 2 | D11: 4 | E11: 5 | F11: 6 | G11: 3 | H11: 10 | I11: p1 - i1:i2 | J11: p5 - i2:i4 | K11: p4 - i4:i5 | L11: p15 - i5:i6 | M11: p131 - i6:i3
A12: 11 | B12: 1 | C12: 2 | D12: 4 | E12: 6 | F12: 3 | G12: 5 | H12: 11 | I12: p1 - i1:i2 | J12: p5 - i2:i4 | K12: p14 - i4:i6 | L12: p131 - i6:i3 | M12: p6 - i3:i5
A13: 12 | B13: 1 | C13: 2 | D13: 4 | E13: 6 | F13: 5 | G13: 3 | H13: 12 | I13: p1 - i1:i2 | J13: p5 - i2:i4 | K13: p14 - i4:i6 | L13: p151 - i6:i5 | M13: p61 - i5:i3
A14: 13 | B14: 1 | C14: 2 | D14: 5 | E14: 3 | F14: 4 | G14: 6 | H14: 13 | I14: p1 - i1:i2 | J14: p7 - i2:i5 | K14: p61 - i5:i3 | L14: p3 - i3:i4 | M14: p14 - i4:i6
... A721: 720 | B721: 6 | C721: 5 | D721: 4 | E721: 3 | F721: 2 | G721: 1 | H721: 720 | I721: p151 - i6:i5 | J721: p41 - i5:i4 | K721: p31 - i4:i3 | L721: p21 - i3:i2 | M721: p11 - i2:i1

Sheet Input and Orientations
A1: User Input | H1: Raw | P1: Ratios | W1: Reference
A2: i1 | B2: i2 | C2: i3 | D2: i4 | E2: i5 | F2: i6 | H2: i1 | I2: i2 | J2: i3 | K2: i4 | L2: i5 | M2: i6 | O2: r1 | P2: =H2 -> i1 | Q2: =I2 -> i2 | R2: =J2 -> i3 | S2: =K2 -> i4 | T2: =L2 -> i5 | U2: =M2 -> i6 | W2: p1 - i1:i2 | X2: p8 - i1:i3 | Y2: p9 - i1:i4 | Z2: p10 - i1:i5 | AA2: p11 - i1:i6
A3: 0 | H3: 0 | I3: =100-H4 -> 50 | J3: =100-H5 -> 31 | K3: =100-H6 -> 64 | L3: =100-H7 -> 76 | M3: =100-H8 -> 53 | P3: 1 | Q3: =I3/H4 -> 1 | R3: =J3/H5 -> 0.44927536 | S3: =K3/H6 -> 1.7777778 | T3: =L3/H7 -> 3.1666667 | U3: =M3/H8 -> 1.1276596 | W3: =$P3/Q3 -> 1 | X3: =$P3/R3 -> 2.2258065 | Y3: =$P3/S3 -> 0.5625 | Z3: =$P3/T3 -> 0.31578947 | AA3: =$P3/U3 -> 0.88679245
A4: 50 | B4: 0 | H4: =A4 -> 50 | I4: 0 | J4: =100-I5 -> 75 | K4: =100-I6 -> 46 | L4: =100-I7 -> 46 | M4: =100-I8 -> 31 | P4: =H4/I3 -> 1 | Q4: 1 | R4: =J4/I5 -> 3 | S4: =K4/I6 -> 0.85185185 | T4: =L4/I7 -> 0.85185185 | U4: =M4/I8 -> 0.44927536 | W4: =$P4/Q4 -> 1 | X4: =$P4/R4 -> 0.33333333 | Y4: =$P4/S4 -> 1.173913 | Z4: =$P4/T4 -> 1.173913 | AA4: =$P4/U4 -> 2.2258065
A5: 69 | B5: 25 | C5: 0 | H5: =A5 -> 69 | I5: =B5 -> 25 | J5: 0 | K5: =100-J6 -> 33 | L5: =100-J7 -> 65 | M5: =100-J8 -> 53 | P5: =H5/J3 -> 2.2258065 | Q5: =I5/J4 -> 0.33333333 | R5: 1 | S5: =K5/J6 -> 0.49253731 | T5: =L5/J7 -> 1.8571429 | U5: =M5/J8 -> 1.1276596 | W5: =$P5/Q5 -> 6.6774194 | X5: =$P5/R5 -> 2.2258065 | Y5: =$P5/S5 -> 4.5190616 | Z5: =$P5/T5 -> 1.1985112 | AA5: =$P5/U5 -> 1.9738284
A6: 36 | B6: 54 | C6: 67 | D6: 0 | H6: =A6 -> 36 | I6: =B6 -> 54 | J6: =C6 -> 67 | K6: 0 | L6: =100-K7 -> 22 | M6: =100-K8 -> 41 | P6: =H6/K3 -> 0.5625 | Q6: =I6/K4 -> 1.173913 | R6: =J6/K5 -> 2.030303 | S6: 1 | T6: =L6/K7 -> 0.28205128 | U6: =M6/K8 -> 0.69491525 | W6: =$P6/Q6 -> 0.47916667 | X6: =$P6/R6 -> 0.27705224 | Y6: =$P6/S6 -> 0.5625 | Z6: =$P6/T6 -> 1.9943182 | AA6: =$P6/U6 -> 0.80945122
A7: 24 | B7: 54 | C7: 35 | D7: 78 | E7: 0 | H7: =A7 -> 24 | I7: =B7 -> 54 | J7: =C7 -> 35 | K7: =D7 -> 78 | L7: 0 | M7: =100-L8 -> 63 | P7: =H7/L3 -> 0.31578947 | Q7: =I7/L4 -> 1.173913 | R7: =J7/L5 -> 0.53846154 | S7: =K7/L6 -> 3.5454545 | T7: 1 | U7: =M7/L8 -> 1.7027027 | W7: =$P7/Q7 -> 0.26900585 | X7: =$P7/R7 -> 0.58646617 | Y7: =$P7/S7 -> 0.089068826 | Z7: =$P7/T7 -> 0.31578947 | AA7: =$P7/U7 -> 0.18546366
A8: 47 | B8: 69 | C8: 47 | D8: 59 | E8: 37 | F8: 0 | H8: =A8 -> 47 | I8: =B8 -> 69 | J8: =C8 -> 47 | K8: =D8 -> 59 | L8: =E8 -> 37 | M8: 0 | P8: =H8/M3 -> 0.88679245 | Q8: =I8/M4 -> 2.2258065 | R8: =J8/M5 -> 0.88679245 | S8: =K8/M6 -> 1.4390244 | T8: =L8/M7 -> 0.58730159 | U8: 1 | W8: =$P8/Q8 -> 0.398414 | X8: =$P8/R8 -> 1 | Y8: =$P8/S8 -> 0.6162456 | Z8: =$P8/T8 -> 1.5099439 | AA8: =$P8/U8 -> 0.88679245
W9: =AVERAGE(W3:W8) -> 1.6373343 | X9: =AVERAGE(X3:X8) -> 1.1080774 | Y9: =AVERAGE(Y3:Y8) -> 1.2538815 | Z9: =AVERAGE(Z3:Z8) -> 1.0847109 | AA9: =AVERAGE(AA3:AA8) -> 1.1613558 | AB9: Average
O11: r2 | P11: =Q2 -> i2 | Q11: =P2 -> i1 | R11: =R2 -> i3 | S11: =S2 -> i4 | T11: =T2 -> i5 | U11: =U2 -> i6 | W11: p11 - i2:i1 | X11: p2 - i2:i3 | Y11: p5 - i2:i4 | Z11: p7 - i2:i5 | AA11: p12 - i2:i6
P12: =Q3 -> 1 | Q12: =P3 -> 1 | R12: =R3 -> 0.44927536 | S12: =S3 -> 1.7777778 | T12: =T3 -> 3.1666667 | U12: =U3 -> 1.1276596 | W12: =$P12/Q12 -> 1 | X12: =$P12/R12 -> 2.2258065 | Y12: =$P12/S12 -> 0.5625 | Z12: =$P12/T12 -> 0.31578947 | AA12: =$P12/U12 -> 0.88679245
P13: =Q4 -> 1 | Q13: =P4 -> 1 | R13: =R4 -> 3 | S13: =S4 -> 0.85185185 | T13: =T4 -> 0.85185185 | U13: =U4 -> 0.44927536 | W13: =$P13/Q13 -> 1 | X13: =$P13/R13 -> 0.33333333 | Y13: =$P13/S13 -> 1.173913 | Z13: =$P13/T13 -> 1.173913 | AA13: =$P13/U13 -> 2.2258065
P14: =Q5 -> 0.33333333 | Q14: =P5 -> 2.2258065 | R14: =R5 -> 1 | S14: =S5 -> 0.49253731 | T14: =T5 -> 1.8571429 | U14: =U5 -> 1.1276596 | W14: =$P14/Q14 -> 0.14975845 | X14: =$P14/R14 -> 0.33333333 | Y14: =$P14/S14 -> 0.67676768 | Z14: =$P14/T14 -> 0.17948718 | AA14: =$P14/U14 -> 0.29559748
P15: =Q6 -> 1.173913 | Q15: =P6 -> 0.5625 | R15: =R6 -> 2.030303 | S15: =S6 -> 1 | T15: =T6 -> 0.28205128 | U15: =U6 -> 0.69491525 | W15: =$P15/Q15 -> 2.0869565 | X15: =$P15/R15 -> 0.57819598 | Y15: =$P15/S15 -> 1.173913 | Z15: =$P15/T15 -> 4.1620553 | AA15: =$P15/U15 -> 1.6892895
P16: =Q7 -> 1.173913 | Q16: =P7 -> 0.31578947 | R16: =R7 -> 0.53846154 | S16: =S7 -> 3.5454545 | T16: =T7 -> 1 | U16: =U7 -> 1.7027027 | W16: =$P16/Q16 -> 3.7173913 | X16: =$P16/R16 -> 2.1801242 | Y16: =$P16/S16 -> 0.33110368 | Z16: =$P16/T16 -> 1.173913 | AA16: =$P16/U16 -> 0.68944099
P17: =Q8 -> 2.2258065 | Q17: =P8 -> 0.88679245 | R17: =R8 -> 0.88679245 | S17: =S8 -> 1.4390244 | T17: =T8 -> 0.58730159 | U17: =U8 -> 1 | W17: =$P17/Q17 -> 2.509952 | X17: =$P17/R17 -> 2.509952 | Y17: =$P17/S17 -> 1.5467469 | Z17: =$P17/T17 -> 3.7898867 | AA17: =$P17/U17 -> 2.2258065
W18: =AVERAGE(W12:W17) -> 1.7440097 | X18: =AVERAGE(X12:X17) -> 1.3601242 | Y18: =AVERAGE(Y12:Y17) -> 0.91082405 | Z18: =AVERAGE(Z12:Z17) -> 1.7991741 | AA18: =AVERAGE(AA12:AA17) -> 1.3354556 | AB18: Average
O20: r3 | P20: =R2 -> i3 | Q20: =P2 -> i1 | R20: =Q2 -> i2 | S20: =S2 -> i4 | T20: =T2 -> i5 | U20: =U2 -> i6 | W20: p81 - i3:i1 | X20: p21 - i3:i2 | Y20: p3 - i3:i4 | Z20: p6 - i3:i5 | AA20: p13 - i3:i6
P21: =R3 -> 0.44927536 | Q21: =P3 -> 1 | R21: =Q3 -> 1 | S21: =S3 -> 1.7777778 | T21: =T3 -> 3.1666667 | U21: =U3 -> 1.1276596 | W21: =$P21/Q21 -> 0.44927536 | X21: =$P21/R21 -> 0.44927536 | Y21: =$P21/S21 -> 0.25271739 | Z21: =$P21/T21 -> 0.14187643 | AA21: =$P21/U21 -> 0.398414
P22: =R4 -> 3 | Q22: =P4 -> 1 | R22: =Q4 -> 1 | S22: =S4 -> 0.85185185 | T22: =T4 -> 0.85185185 | U22: =U4 -> 0.44927536 | W22: =$P22/Q22 -> 3 | X22: =$P22/R22 -> 3 | Y22: =$P22/S22 -> 3.5217391 | Z22: =$P22/T22 -> 3.5217391 | AA22: =$P22/U22 -> 6.6774194
P23: =R5 -> 1 | Q23: =P5 -> 2.2258065 | R23: =Q5 -> 0.33333333 | S23: =S5 -> 0.49253731 | T23: =T5 -> 1.8571429 | U23: =U5 -> 1.1276596 | W23: =$P23/Q23 -> 0.44927536 | X23: =$P23/R23 -> 3 | Y23: =$P23/S23 -> 2.030303 | Z23: =$P23/T23 -> 0.53846154 | AA23: =$P23/U23 -> 0.88679245
P24: =R6 -> 2.030303 | Q24: =P6 -> 0.5625 | R24: =Q6 -> 1.173913 | S24: =S6 -> 1 | T24: =T6 -> 0.28205128 | U24: =U6 -> 0.69491525 | W24: =$P24/Q24 -> 3.6094276 | X24: =$P24/R24 -> 1.7295174 | Y24: =$P24/S24 -> 2.030303 | Z24: =$P24/T24 -> 7.1983471 | AA24: =$P24/U24 -> 2.9216556
P25: =R7 -> 0.53846154 | Q25: =P7 -> 0.31578947 | R25: =Q7 -> 1.173913 | S25: =S7 -> 3.5454545 | T25: =T7 -> 1 | U25: =U7 -> 1.7027027 | W25: =$P25/Q25 -> 1.7051282 | X25: =$P25/R25 -> 0.45868946 | Y25: =$P25/S25 -> 0.15187377 | Z25: =$P25/T25 -> 0.53846154 | AA25: =$P25/U25 -> 0.31623932
P26: =R8 -> 0.88679245 | Q26: =P8 -> 0.88679245 | R26: =Q8 -> 2.2258065 | S26: =S8 -> 1.4390244 | T26: =T8 -> 0.58730159 | U26: =U8 -> 1 | W26: =$P26/Q26 -> 1 | X26: =$P26/R26 -> 0.398414 | Y26: =$P26/S26 -> 0.6162456 | Z26: =$P26/T26 -> 1.5099439 | AA26: =$P26/U26 -> 0.88679245
W27: =AVERAGE(W21:W26) -> 1.7021844 | X27: =AVERAGE(X21:X26) -> 1.5059827 | Y27: =AVERAGE(Y21:Y26) -> 1.4338637 | Z27: =AVERAGE(Z21:Z26) -> 2.2414716 | AA27: =AVERAGE(AA21:AA26) -> 2.0145522 | AB27: Average
O29: r4 | P29: =S2 -> i4 | Q29: =P2 -> i1 | R29: =Q2 -> i2 | S29: =R2 -> i3 | T29: =T2 -> i5 | U29: =U2 -> i6 | W29: p91 - i4:i1 | X29: p51 - i4:i2 | Y29: p31 - i4:i3 | Z29: p4 - i4:i5 | AA29: p14 - i4:i6
P30: =S3 -> 1.7777778 | Q30: =P3 -> 1 | R30: =Q3 -> 1 | S30: =R3 -> 0.44927536 | T30: =T3 -> 3.1666667 | U30: =U3 -> 1.1276596 | W30: =$P30/Q30 -> 1.7777778 | X30: =$P30/R30 -> 1.7777778 | Y30: =$P30/S30 -> 3.9569892 | Z30: =$P30/T30 -> 0.56140351 | AA30: =$P30/U30 -> 1.5765199
P31: =S4 -> 0.85185185 | Q31: =P4 -> 1 | R31: =Q4 -> 1 | S31: =R4 -> 3 | T31: =T4 -> 0.85185185 | U31: =U4 -> 0.44927536 | W31: =$P31/Q31 -> 0.85185185 | X31: =$P31/R31 -> 0.85185185 | Y31: =$P31/S31 -> 0.28395062 | Z31: =$P31/T31 -> 1 | AA31: =$P31/U31 -> 1.8960573
P32: =S5 -> 0.49253731 | Q32: =P5 -> 2.2258065 | R32: =Q5 -> 0.33333333 | S32: =R5 -> 1 | T32: =T5 -> 1.8571429 | U32: =U5 -> 1.1276596 | W32: =$P32/Q32 -> 0.22128488 | X32: =$P32/R32 -> 1.4776119 | Y32: =$P32/S32 -> 0.49253731 | Z32: =$P32/T32 -> 0.2652124 | AA32: =$P32/U32 -> 0.43677837
P33: =S6 -> 1 | Q33: =P6 -> 0.5625 | R33: =Q6 -> 1.173913 | S33: =R6 -> 2.030303 | T33: =T6 -> 0.28205128 | U33: =U6 -> 0.69491525 | W33: =$P33/Q33 -> 1.7777778 | X33: =$P33/R33 -> 0.85185185 | Y33: =$P33/S33 -> 0.49253731 | Z33: =$P33/T33 -> 3.5454545 | AA33: =$P33/U33 -> 1.4390244
P34: =S7 -> 3.5454545 | Q34: =P7 -> 0.31578947 | R34: =Q7 -> 1.173913 | S34: =R7 -> 0.53846154 | T34: =T7 -> 1 | U34: =U7 -> 1.7027027 | W34: =$P34/Q34 -> 11.227273 | X34: =$P34/R34 -> 3.020202 | Y34: =$P34/S34 -> 6.5844156 | Z34: =$P34/T34 -> 3.5454545 | AA34: =$P34/U34 -> 2.0822511
P35: =S8 -> 1.4390244 | Q35: =P8 -> 0.88679245 | R35: =Q8 -> 2.2258065 | S35: =R8 -> 0.88679245 | T35: =T8 -> 0.58730159 | U35: =U8 -> 1 | W35: =$P35/Q35 -> 1.6227296 | X35: =$P35/R35 -> 0.6465182 | Y35: =$P35/S35 -> 1.6227296 | Z35: =$P35/T35 -> 2.4502307 | AA35: =$P35/U35 -> 1.4390244
W36: =AVERAGE(W30:W35) -> 2.9131158 | X36: =AVERAGE(X30:X35) -> 1.4376356 | Y36: =AVERAGE(Y30:Y35) -> 2.23886 | Z36: =AVERAGE(Z30:Z35) -> 1.894626 | AA36: =AVERAGE(AA30:AA35) -> 1.4782759 | AB36: Average
O38: r5 | P38: =T2 -> i5 | Q38: =P2 -> i1 | R38: =Q2 -> i2 | S38: =R2 -> i3 | T38: =S2 -> i4 | U38: =U2 -> i6 | W38: p101 - i5:i1 | X38: p71 - i5:i2 | Y38: p61 - i5:i3 | Z38: p41 - i5:i4 | AA38: p15 - i5:i6
P39: =T3 -> 3.1666667 | Q39: =P3 -> 1 | R39: =Q3 -> 1 | S39: =R3 -> 0.44927536 | T39: =S3 -> 1.7777778 | U39: =U3 -> 1.1276596 | W39: =$P39/Q39 -> 3.1666667 | X39: =$P39/R39 -> 3.1666667 | Y39: =$P39/S39 -> 7.0483871 | Z39: =$P39/T39 -> 1.78125 | AA39: =$P39/U39 -> 2.8081761
P40: =T4 -> 0.85185185 | Q40: =P4 -> 1 | R40: =Q4 -> 1 | S40: =R4 -> 3 | T40: =S4 -> 0.85185185 | U40: =U4 -> 0.44927536 | W40: =$P40/Q40 -> 0.85185185 | X40: =$P40/R40 -> 0.85185185 | Y40: =$P40/S40 -> 0.28395062 | Z40: =$P40/T40 -> 1 | AA40: =$P40/U40 -> 1.8960573
P41: =T5 -> 1.8571429 | Q41: =P5 -> 2.2258065 | R41: =Q5 -> 0.33333333 | S41: =R5 -> 1 | T41: =S5 -> 0.49253731 | U41: =U5 -> 1.1276596 | W41: =$P41/Q41 -> 0.83436853 | X41: =$P41/R41 -> 5.5714286 | Y41: =$P41/S41 -> 1.8571429 | Z41: =$P41/T41 -> 3.7705628 | AA41: =$P41/U41 -> 1.6469003
P42: =T6 -> 0.28205128 | Q42: =P6 -> 0.5625 | R42: =Q6 -> 1.173913 | S42: =R6 -> 2.030303 | T42: =S6 -> 1 | U42: =U6 -> 0.69491525 | W42: =$P42/Q42 -> 0.5014245 | X42: =$P42/R42 -> 0.24026591 | Y42: =$P42/S42 -> 0.13892078 | Z42: =$P42/T42 -> 0.28205128 | AA42: =$P42/U42 -> 0.40587867
P43: =T7 -> 1 | Q43: =P7 -> 0.31578947 | R43: =Q7 -> 1.173913 | S43: =R7 -> 0.53846154 | T43: =S7 -> 3.5454545 | U43: =U7 -> 1.7027027 | W43: =$P43/Q43 -> 3.1666667 | X43: =$P43/R43 -> 0.85185185 | Y43: =$P43/S43 -> 1.8571429 | Z43: =$P43/T43 -> 0.28205128 | AA43: =$P43/U43 -> 0.58730159
P44: =T8 -> 0.58730159 | Q44: =P8 -> 0.88679245 | R44: =Q8 -> 2.2258065 | S44: =R8 -> 0.88679245 | T44: =S8 -> 1.4390244 | U44: =U8 -> 1 | W44: =$P44/Q44 -> 0.66227626 | X44: =$P44/R44 -> 0.26386013 | Y44: =$P44/S44 -> 0.66227626 | Z44: =$P44/T44 -> 0.40812483 | AA44: =$P44/U44 -> 0.58730159
...

Sheet Vlookup
A1: ='Input and Orientations'!W2 -> p1 - i1:i2 | B1: ='Input and Orientations'!W9 -> 1.6373343
A2: ='Input and Orientations'!X2 -> p8 - i1:i3 | B2: ='Input and Orientations'!X9 -> 1.1080774
A3: ='Input and Orientations'!Y2 -> p9 - i1:i4 | B3: ='Input and Orientations'!Y9 -> 1.2538815
A4: ='Input and Orientations'!Z2 -> p10 - i1:i5 | B4: ='Input and Orientations'!Z9 -> 1.0847109
A5: ='Input and Orientations'!AA2 -> p11 - i1:i6 | B5: ='Input and Orientations'!AA9 -> 1.1613558
A6: ='Input and Orientations'!W11 -> p11 - i2:i1 | B6: ='Input and Orientations'!W18 -> 1.7440097
A7: ='Input and Orientations'!X11 -> p2 - i2:i3 | B7: ='Input and Orientations'!X18 -> 1.3601242
A8: ='Input and Orientations'!Y11 -> p5 - i2:i4 | B8: ='Input and Orientations'!Y18 -> 0.91082405
A9: ='Input and Orientations'!Z11 -> p7 - i2:i5 | B9: ='Input and Orientations'!Z18 -> 1.7991741
A10: ='Input and Orientations'!AA11 -> p12 - i2:i6 | B10: ='Input and Orientations'!AA18 -> 1.3354556
A11: ='Input and Orientations'!W20 -> p81 - i3:i1 | B11: ='Input and Orientations'!W27 -> 1.7021844
A12: ='Input and Orientations'!X20 -> p21 - i3:i2 | B12: ='Input and Orientations'!X27 -> 1.5059827
A13: ='Input and Orientations'!Y20 -> p3 - i3:i4 | B13: ='Input and Orientations'!Y27 -> 1.4338637
A14: ='Input and Orientations'!Z20 -> p6 - i3:i5 | B14: ='Input and Orientations'!Z27 -> 2.2414716
A15: ='Input and Orientations'!AA20 -> p13 - i3:i6 | B15: ='Input and Orientations'!AA27 -> 2.0145522
A16: ='Input and Orientations'!W29 -> p91 - i4:i1 | B16: ='Input and Orientations'!W36 -> 2.9131158
A17: ='Input and Orientations'!X29 -> p51 - i4:i2 | B17: ='Input and Orientations'!X36 -> 1.4376356
A18: ='Input and Orientations'!Y29 -> p31 - i4:i3 | B18: ='Input and Orientations'!Y36 -> 2.23886
A19: ='Input and Orientations'!Z29 -> p4 - i4:i5 | B19: ='Input and Orientations'!Z36 -> 1.894626
A20: ='Input and Orientations'!AA29 -> p14 - i4:i6 | B20: ='Input and Orientations'!AA36 -> 1.4782759
A21: ='Input and Orientations'!W38 -> p101 - i5:i1 | B21: ='Input and Orientations'!W45 -> 1.5305424
A22: ='Input and Orientations'!X38 -> p71 - i5:i2 | B22: ='Input and Orientations'!X45 -> 1.8243208
A23: ='Input and Orientations'!Y38 -> p61 - i5:i3 | B23: ='Input and Orientations'!Y45 -> 1.9746367
A24: ='Input and Orientations'!Z38 -> p41 - i5:i4 | B24: ='Input and Orientations'!Z45 -> 1.2540067
A25: ='Input and Orientations'!AA38 -> p15 - i5:i6 | B25: ='Input and Orientations'!AA45 -> 1.3219359
A26: ='Input and Orientations'!W47 -> p111 - i6:i1 | B26: ='Input and Orientations'!W54 -> 1.6397535
A27: ='Input and Orientations'!X47 -> p121 - i6:i2 | B27: ='Input and Orientations'!X54 -> 1.2419341
A28: ='Input and Orientations'!Y47 -> p131 - i6:i3 | B28: ='Input and Orientations'!Y54 -> 1.4032439
A29: ='Input and Orientations'!Z47 -> p141 - i6:i4 | B29: ='Input and Orientations'!Z54 -> 0.88688156
A30: ='Input and Orientations'!AA47 -> p151 - i6:i5 | B30: ='Input and Orientations'!AA54 -> 1.2266517

Sheet Rankings
B1: Ratios | C1: ='Input and Orientations'!P2 -> i1 | D1: ='Input and Orientations'!Q2 -> i2 | E1: ='Input and Orientations'!R2 -> i3 | F1: ='Input and Orientations'!S2 -> i4 | G1: ='Input and Orientations'!T2 -> i5 | H1: ='Input and Orientations'!U2 -> i6 | I1: sum
B2: i1 | C2: ='Input and Orientations'!P3 -> 1 | D2: ='Input and Orientations'!Q3 -> 1 | E2: ='Input and Orientations'!R3 -> 0.44927536 | F2: ='Input and Orientations'!S3 -> 1.7777778 | G2: ='Input and Orientations'!T3 -> 3.1666667 | H2: ='Input and Orientations'!U3 -> 1.1276596 | I2: =SUM(C2:H2) -> 8.5213794
B3: i2 | C3: ='Input and Orientations'!P4 -> 1 | D3: ='Input and Orientations'!Q4 -> 1 | E3: ='Input and Orientations'!R4 -> 3 | F3: ='Input and Orientations'!S4 -> 0.85185185 | G3: ='Input and Orientations'!T4 -> 0.85185185 | H3: ='Input and Orientations'!U4 -> 0.44927536 | I3: =SUM(C3:H3) -> 7.1529791
B4: i3 | C4: ='Input and Orientations'!P5 -> 2.2258065 | D4: ='Input and Orientations'!Q5 -> 0.33333333 | E4: ='Input and Orientations'!R5 -> 1 | F4: ='Input and Orientations'!S5 -> 0.49253731 | G4: ='Input and Orientations'!T5 -> 1.8571429 | H4: ='Input and Orientations'!U5 -> 1.1276596 | I4: =SUM(C4:H4) -> 7.0364795
B5: i4 | C5: ='Input and Orientations'!P6 -> 0.5625 | D5: ='Input and Orientations'!Q6 -> 1.173913 | E5: ='Input and Orientations'!R6 -> 2.030303 | F5: ='Input and Orientations'!S6 -> 1 | G5: ='Input and Orientations'!T6 -> 0.28205128 | H5: ='Input and Orientations'!U6 -> 0.69491525 | I5: =SUM(C5:H5) -> 5.7436826
B6: i5 | C6: ='Input and Orientations'!P7 -> 0.31578947 | D6: ='Input and Orientations'!Q7 -> 1.173913 | E6: ='Input and Orientations'!R7 -> 0.53846154 | F6: ='Input and Orientations'!S7 -> 3.5454545 | G6: ='Input and Orientations'!T7 -> 1 | H6: ='Input and Orientations'!U7 -> 1.7027027 | I6: =SUM(C6:H6) -> 8.2763213
B7: i6 | C7: ='Input and Orientations'!P8 -> 0.88679245 | D7: ='Input and Orientations'!Q8 -> 2.2258065 | E7: ='Input and Orientations'!R8 -> 0.88679245 | F7: ='Input and Orientations'!S8 -> 1.4390244 | G7: ='Input and Orientations'!T8 -> 0.58730159 | H7: ='Input and Orientations'!U8 -> 1 | I7: =SUM(C7:H7) -> 7.0257173
B9: Vlookup # | G9: Orientations | L9: Raw Weights | Q9: Make sure this row is all 1's (this is needed to get the Sum Raw Weights to equal the Abbas example) | R9: Sum Raw Weights | S9: Normalized
A10: 1 | B10: =Permutations!I2 -> p1 - i1:i2 | C10: =Permutations!J2 -> p2 - i2:i3 | D10: =Permutations!K2 -> p3 - i3:i4 | E10: =Permutations!L2 -> p4 - i4:i5 | F10: =Permutations!M2 -> p15 - i5:i6 | G10: =VLOOKUP(B10,Vlookup!$A$1:$B$30,2,0) -> 1.6373343 | H10: =VLOOKUP(C10,Vlookup!$A$1:$B$30,2,0) -> 1.3601242 | I10: =VLOOKUP(D10,Vlookup!$A$1:$B$30,2,0) -> 1.4338637 | J10: =VLOOKUP(E10,Vlookup!$A$1:$B$30,2,0) -> 1.894626 | K10: =VLOOKUP(F10,Vlookup!$A$1:$B$30,2,0) -> 1.3219359 | L10: =G10*H10*I10*J10*K10 -> 7.9975632 | M10: =H10*I10*J10*K10 -> 4.8845023 | N10: =I10*J10*K10 -> 3.5912178 | O10: =J10*K10 -> 2.5045741 | P10: =K10 -> 1.3219359 | Q10: 1 | R10: =SUM(L10:Q10) -> 21.299793 | S10: =VLOOKUP($A10,Rotations!$A$1:$X$1441,18,0) -> 0.37547609 | T10: =VLOOKUP($A10,Rotations!$A$1:$X$1441,19,0) -> 0.22932158 | U10: =VLOOKUP($A10,Rotations!$A$1:$X$1441,20,0) -> 0.16860341 | V10: =VLOOKUP($A10,Rotations!$A$1:$X$1441,21,0) -> 0.11758678 | W10: =VLOOKUP($A10,Rotations!$A$1:$X$1441,22,0) -> 0.062063322 | X10: =VLOOKUP($A10,Rotations!$A$1:$X$1441,23,0) -> 0.046948812
A11: 2 | B11: =Permutations!I3 -> p1 - i1:i2 | C11: =Permutations!J3 -> p2 - i2:i3 | D11: =Permutations!K3 -> p3 - i3:i4 | E11: =Permutations!L3 -> p14 - i4:i6 | F11: =Permutations!M3 -> p151 - i6:i5 | G11: =VLOOKUP(B11,Vlookup!$A$1:$B$30,2,0) -> 1.6373343 | H11: =VLOOKUP(C11,Vlookup!$A$1:$B$30,2,0) -> 1.3601242 | I11: =VLOOKUP(D11,Vlookup!$A$1:$B$30,2,0) -> 1.4338637 | J11: =VLOOKUP(E11,Vlookup!$A$1:$B$30,2,0) -> 1.4782759 | K11: =VLOOKUP(F11,Vlookup!$A$1:$B$30,2,0) -> 1.2266517 | L11: =G11*H11*I11*J11*K11 -> 5.7902934 | M11: =H11*I11*J11*K11 -> 3.5364149 | N11: =I11*J11*K11 -> 2.6000676 | O11: =J11*K11 -> 1.8133297 | P11: =K11 -> 1.2266517 | Q11: 1 | R11: =SUM(L11:Q11) -> 15.966757 | S11: =VLOOKUP($A11,Rotations!$A$1:$X$1441,18,0) -> 0.3626468 | T11: =VLOOKUP($A11,Rotations!$A$1:$X$1441,19,0) -> 0.2214861 | U11: =VLOOKUP($A11,Rotations!$A$1:$X$1441,20,0) -> 0.16284256 | V11: =VLOOKUP($A11,Rotations!$A$1:$X$1441,21,0) -> 0.11356907 | W11: =VLOOKUP($A11,Rotations!$A$1:$X$1441,22,0) -> 0.062630125 | X11: =VLOOKUP($A11,Rotations!$A$1:$X$1441,23,0) -> 0.076825351
A12: 3 | B12: =Permutations!I4 -> p1 - i1:i2 | C12: =Permutations!J4 -> p2 - i2:i3 | D12: =Permutations!K4 -> p6 - i3:i5 | E12: =Permutations!L4 -> p41 - i5:i4 | F12: =Permutations!M4 -> p14 - i4:i6 | G12: =VLOOKUP(B12,Vlookup!$A$1:$B$30,2,0) -> 1.6373343 | H12: =VLOOKUP(C12,Vlookup!$A$1:$B$30,2,0) -> 1.3601242 | I12: =VLOOKUP(D12,Vlookup!$A$1:$B$30,2,0) -> 2.2414716 | J12: =VLOOKUP(E12,Vlookup!$A$1:$B$30,2,0) -> 1.2540067 | K12: =VLOOKUP(F12,Vlookup!$A$1:$B$30,2,0) -> 1.4782759 | L12: =G12*H12*I12*J12*K12 -> 9.2534681 | M12: =H12*I12*J12*K12 -> 5.6515447 | N12: =I12*J12*K12 -> 4.1551681 | O12: =J12*K12 -> 1.8537679 | P12: =K12 -> 1.4782759 | Q12: 1 | R12: =SUM(L12:Q12) -> 23.392225 | S12: =VLOOKUP($A12,Rotations!$A$1:$X$1441,18,0) -> 0.3955788 | T12: =VLOOKUP($A12,Rotations!$A$1:$X$1441,19,0) -> 0.24159928 | U12: =VLOOKUP($A12,Rotations!$A$1:$X$1441,20,0) -> 0.17763031 | V12: =VLOOKUP($A12,Rotations!$A$1:$X$1441,21,0) -> 0.063195183 | W12: =VLOOKUP($A12,Rotations!$A$1:$X$1441,22,0) -> 0.079247182 | X12: =VLOOKUP($A12,Rotations!$A$1:$X$1441,23,0) -> 0.042749247
A13: 4 | B13: =Permutations!I5 -> p1 - i1:i2 | C13: =Permutations!J5 -> p2 - i2:i3 | D13: =Permutations!K5 -> p6 - i3:i5 | E13: =Permutations!L5 -> p15 - i5:i6 | F13: =Permutations!M5 -> p141 - i6:i4 | G13: =VLOOKUP(B13,Vlookup!$A$1:$B$30,2,0) -> 1.6373343 | H13: =VLOOKUP(C13,Vlookup!$A$1:$B$30,2,0) -> 1.3601242 | I13: =VLOOKUP(D13,Vlookup!$A$1:$B$30,2,0) -> 2.2414716 | J13: =VLOOKUP(E13,Vlookup!$A$1:$B$30,2,0) -> 1.3219359 | K13: =VLOOKUP(F13,Vlookup!$A$1:$B$30,2,0) -> 0.88688156 | L13: =G13*H13*I13*J13*K13 -> 5.8522815 | M13: =H13*I13*J13*K13 -> 3.574274 | N13: =I13*J13*K13 -> 2.6279027 | O13: =J13*K13 -> 1.1724006 | P13: =K13 -> 0.88688156 | Q13: 1 | R13: =SUM(L13:Q13) -> 15.11374 | S13: =VLOOKUP($A13,Rotations!$A$1:$X$1441,18,0) -> 0.38721596 | T13: =VLOOKUP($A13,Rotations!$A$1:$X$1441,19,0) -> 0.23649169 | U13: =VLOOKUP($A13,Rotations!$A$1:$X$1441,20,0) -> 0.17387507 | V13: =VLOOKUP($A13,Rotations!$A$1:$X$1441,21,0) -> 0.066164958 | W13: =VLOOKUP($A13,Rotations!$A$1:$X$1441,22,0) -> 0.077571837 | X13: =VLOOKUP($A13,Rotations!$A$1:$X$1441,23,0) -> 0.058680481
A14: 5 | B14: =Permutations!I6 -> p1 - i1:i2 | C14: =Permutations!J6 -> p2 - i2:i3 | D14: =Permutations!K6 -> p13 - i3:i6 | E14: =Permutations!L6 -> p141 - i6:i4 | F14: =Permutations!M6 -> p4 - i4:i5 | G14: =VLOOKUP(B14,Vlookup!$A$1:$B$30,2,0) -> 1.6373343 | H14: =VLOOKUP(C14,Vlookup!$A$1:$B$30,2,0) -> 1.3601242 | I14: =VLOOKUP(D14,Vlookup!$A$1:$B$30,2,0) -> 2.0145522 | J14: =VLOOKUP(E14,Vlookup!$A$1:$B$30,2,0) -> 0.88688156 | K14: =VLOOKUP(F14,Vlookup!$A$1:$B$30,2,0) -> 1.894626 | L14: =G14*H14*I14*J14*K14 -> 7.5384762 | M14: =H14*I14*J14*K14 -> 4.6041154 | N14: =I14*J14*K14 -> 3.3850698 | O14: =J14*K14 -> 1.6803088 | P14: =K14 -> 1.894626 | Q14: 1 | R14: =SUM(L14:Q14) -> 20.102596 | S14: =VLOOKUP($A14,Rotations!$A$1:$X$1441,18,0) -> 0.37500013 | T14: =VLOOKUP($A14,Rotations!$A$1:$X$1441,19,0) -> 0.22903089 | U14: =VLOOKUP($A14,Rotations!$A$1:$X$1441,20,0) -> 0.16838968 | V14: =VLOOKUP($A14,Rotations!$A$1:$X$1441,21,0) -> 0.094247824 | W14: =VLOOKUP($A14,Rotations!$A$1:$X$1441,22,0) -> 0.049744819 | X14: =VLOOKUP($A14,Rotations!$A$1:$X$1441,23,0) -> 0.083586657
A15: 6 | B15: =Permutations!I7 -> p1 - i1:i2 | C15: =Permutations!J7 -> p2 - i2:i3 | D15: =Permutations!K7 -> p13 - i3:i6 | E15: =Permutations!L7 -> p151 - i6:i5 | F15: =Permutations!M7 -> p41 - i5:i4 | G15: =VLOOKUP(B15,Vlookup!$A$1:$B$30,2,0) -> 1.6373343 | H15: =VLOOKUP(C15,Vlookup!$A$1:$B$30,2,0) -> 1.3601242 | I15: =VLOOKUP(D15,Vlookup!$A$1:$B$30,2,0) -> 2.0145522 | J15: =VLOOKUP(E15,Vlookup!$A$1:$B$30,2,0) -> 1.2266517 | K15: =VLOOKUP(F15,Vlookup!$A$1:$B$30,2,0) -> 1.2540067 | L15: =G15*H15*I15*J15*K15 -> 6.9010566 | M15: =H15*I15*J15*K15 -> 4.2148122 | N15: =I15*J15*K15 -> 3.0988436 | O15: =J15*K15 -> 1.5382295 | P15: =K15 -> 1.2540067 | Q15: 1 | R15: =SUM(L15:Q15) -> 18.006949 | S15: =VLOOKUP($A15,Rotations!$A$1:$X$1441,18,0) -> 0.38324409 | T15: =VLOOKUP($A15,Rotations!$A$1:$X$1441,19,0) -> 0.23406588 | U15: =VLOOKUP($A15,Rotations!$A$1:$X$1441,20,0) -> 0.17209154 | V15: =VLOOKUP($A15,Rotations!$A$1:$X$1441,21,0) -> 0.055534118 | W15: =VLOOKUP($A15,Rotations!$A$1:$X$1441,22,0) -> 0.069640155 | X15: =VLOOKUP($A15,Rotations!$A$1:$X$1441,23,0) -> 0.085424217
A16: 7 | B16: =Permutations!I8 -> p1 - i1:i2 | C16: =Permutations!J8 -> p5 - i2:i4 | D16: =Permutations!K8 -> p31 - i4:i3 | E16: =Permutations!L8 -> p6 - i3:i5 | F16: =Permutations!M8 -> p15 - i5:i6 | G16: =VLOOKUP(B16,Vlookup!$A$1:$B$30,2,0) -> 1.6373343 | H16: =VLOOKUP(C16,Vlookup!$A$1:$B$30,2,0) -> 0.91082405 | I16: =VLOOKUP(D16,Vlookup!$A$1:$B$30,2,0) -> 2.23886 | J16: =VLOOKUP(E16,Vlookup!$A$1:$B$30,2,0) -> 2.2414716 | K16: =VLOOKUP(F16,Vlookup!$A$1:$B$30,2,0) -> 1.3219359 | L16: =G16*H16*I16*J16*K16 -> 9.8933285 | M16: =H16*I16*J16*K16 -> 6.0423387 | N16: =I16*J16*K16 -> 6.6339253 | O16: =J16*K16 -> 2.9630819 | P16: =K16 -> 1.3219359 | Q16: 1 | R16: =SUM(L16:Q16) -> 27.85461 | S16: =VLOOKUP($A16,Rotations!$A$1:$X$1441,18,0) -> 0.35517742 | T16: =VLOOKUP($A16,Rotations!$A$1:$X$1441,19,0) -> 0.21692419 | U16: =VLOOKUP($A16,Rotations!$A$1:$X$1441,20,0) -> 0.10637671 | V16: =VLOOKUP($A16,Rotations!$A$1:$X$1441,21,0) -> 0.23816256 | W16: =VLOOKUP($A16,Rotations!$A$1:$X$1441,22,0) -> 0.047458425 | X16: =VLOOKUP($A16,Rotations!$A$1:$X$1441,23,0) -> 0.0359007
A17: 8 | B17: =Permutations!I9 -> p1 - i1:i2 | C17: =Permutations!J9 -> p5 - i2:i4 | D17: =Permutations!K9 -> p31 - i4:i3 | E17: =Permutations!L9 -> p13 - i3:i6 | F17: =Permutations!M9 -> p151 - i6:i5 | G17: =VLOOKUP(B17,Vlookup!$A$1:$B$30,2,0) -> 1.6373343 | H17: =VLOOKUP(C17,Vlookup!$A$1:$B$30,2,0) -> 0.91082405 | I17: =VLOOKUP(D17,Vlookup!$A$1:$B$30,2,0) -> 2.23886 | J17: =VLOOKUP(E17,Vlookup!$A$1:$B$30,2,0) -> 2.0145522 | K17: =VLOOKUP(F17,Vlookup!$A$1:$B$30,2,0) -> 1.2266517 | L17: =G17*H17*I17*J17*K17 -> 8.2508479 | M17: =H17*I17*J17*K17 -> 5.0391956 | N17: =I17*J17*K17 -> 5.5325676 | O17: =J17*K17 -> 2.4711539 | P17: =K17 -> 1.2266517 | Q17: 1 | R17: =SUM(L17:Q17) -> 23.520417 | S17: =VLOOKUP($A17,Rotations!$A$1:$X$1441,18,0) -> 0.35079514 | T17: =VLOOKUP($A17,Rotations!$A$1:$X$1441,19,0) -> 0.21424772 | U17: =VLOOKUP($A17,Rotations!$A$1:$X$1441,20,0) -> 0.10506421 | V17: =VLOOKUP($A17,Rotations!$A$1:$X$1441,21,0) -> 0.23522405 | W17: =VLOOKUP($A17,Rotations!$A$1:$X$1441,22,0) -> 0.042516253 | X17: =VLOOKUP($A17,Rotations!$A$1:$X$1441,23,0) -> 0.052152636
A18: 9 | B18: =Permutations!I10 -> p1 - i1:i2 | C18: =Permutations!J10 -> p5 - i2:i4 | D18: =Permutations!K10 -> p4 - i4:i5 | E18: =Permutations!L10 -> p61 - i5:i3 | F18: =Permutations!M10 -> p13 - i3:i6 | G18: =VLOOKUP(B18,Vlookup!$A$1:$B$30,2,0) -> 1.6373343 | H18: =VLOOKUP(C18,Vlookup!$A$1:$B$30,2,0) -> 0.91082405 | I18: =VLOOKUP(D18,Vlookup!$A$1:$B$30,2,0) -> 1.894626 | J18: =VLOOKUP(E18,Vlookup!$A$1:$B$30,2,0) -> 1.9746367 | K18: =VLOOKUP(F18,Vlookup!$A$1:$B$30,2,0) -> 2.0145522 | L18: =G18*H18*I18*J18*K18 -> 11.239864 | M18: =H18*I18*J18*K18 -> 6.8647339 | N18: =I18*J18*K18 -> 7.5368387 | O18: =J18*K18 -> 3.9780088 | P18: =K18 -> 2.0145522 | Q18: 1 | R18: =SUM(L18:Q18) -> 32.633998 | S18: =VLOOKUP($A18,Rotations!$A$1:$X$1441,18,0) -> 0.34442192 | T18: =VLOOKUP($A18,Rotations!$A$1:$X$1441,19,0) -> 0.21035528 | U18: =VLOOKUP($A18,Rotations!$A$1:$X$1441,20,0) -> 0.061731701 | V18: =VLOOKUP($A18,Rotations!$A$1:$X$1441,21,0) -> 0.23095052 | W18: =VLOOKUP($A18,Rotations!$A$1:$X$1441,22,0) -> 0.12189768 | X18: =VLOOKUP($A18,Rotations!$A$1:$X$1441,23,0) -> 0.03064289
A19: 10 | B19: =Permutations!I11 -> p1 - i1:i2 | C19: =Permutations!J11 -> p5 - i2:i4 | D19: =Permutations!K11 -> p4 - i4:i5 | E19: =Permutations!L11 -> p15 - i5:i6 | F19: =Permutations!M11 -> p131 - i6:i3 | G19: =VLOOKUP(B19,Vlookup!$A$1:$B$30,2,0) -> 1.6373343 | H19: =VLOOKUP(C19,Vlookup!$A$1:$B$30,2,0) -> 0.91082405 | I19: =VLOOKUP(D19,Vlookup!$A$1:$B$30,2,0) -> 1.894626 | J19: =VLOOKUP(E19,Vlookup!$A$1:$B$30,2,0) -> 1.3219359 | K19: =VLOOKUP(F19,Vlookup!$A$1:$B$30,2,0) -> 1.4032439 | L19: =G19*H19*I19*J19*K19 -> 5.2412986 | M19: =H19*I19*J19*K19 -> 3.201117 | N19: =I19*J19*K19 -> 3.5145284 | O19: =J19*K19 -> 1.8549985 | P19: =K19 -> 1.4032439 | Q19: 1 | R19: =SUM(L19:Q19) -> 16.215186 | S19: =VLOOKUP($A19,Rotations!$A$1:$X$1441,18,0) -> 0.32323394 | T19: =VLOOKUP($A19,Rotations!$A$1:$X$1441,19,0) -> 0.19741475 | U19: =VLOOKUP($A19,Rotations!$A$1:$X$1441,20,0) -> 0.061670583 | V19: =VLOOKUP($A19,Rotations!$A$1:$X$1441,21,0) -> 0.21674301 | W19: =VLOOKUP($A19,Rotations!$A$1:$X$1441,22,0) -> 0.11439884 | X19: =VLOOKUP($A19,Rotations!$A$1:$X$1441,23,0) -> 0.08653887
A20: 11 | B20: =Permutations!I12 -> p1 - i1:i2 | C20: =Permutations!J12 -> p5 - i2:i4 | D20: =Permutations!K12 -> p14 - i4:i6 | E20: =Permutations!L12 -> p131 - i6:i3 | F20: =Permutations!M12 -> p6 - i3:i5 | G20: =VLOOKUP(B20,Vlookup!$A$1:$B$30,2,0) -> 1.6373343 | H20: =VLOOKUP(C20,Vlookup!$A$1:$B$30,2,0) -> 0.91082405 | I20: =VLOOKUP(D20,Vlookup!$A$1:$B$30,2,0) -> 1.4782759 | J20: =VLOOKUP(E20,Vlookup!$A$1:$B$30,2,0) -> 1.4032439 | K20: =VLOOKUP(F20,Vlookup!$A$1:$B$30,2,0) -> 2.2414716 | L20: =G20*H20*I20*J20*K20 -> 6.9341584 | M20: =H20*I20*J20*K20 -> 4.2350291 | N20: =I20*J20*K20 -> 4.6496676 | O20: =J20*K20 -> 3.1453314 | P20: =K20 -> 2.2414716 | Q20: 1 | R20: =SUM(L20:Q20) -> 22.205658 | S20: =VLOOKUP($A20,Rotations!$A$1:$X$1441,18,0) -> 0.31226989 | T20: =VLOOKUP($A20,Rotations!$A$1:$X$1441,19,0) -> 0.19071847 | U20: =VLOOKUP($A20,Rotations!$A$1:$X$1441,20,0) -> 0.10094146 | V20: =VLOOKUP($A20,Rotations!$A$1:$X$1441,21,0) -> 0.20939112 | W20: =VLOOKUP($A20,Rotations!$A$1:$X$1441,22,0) -> 0.045033567 | X20: =VLOOKUP($A20,Rotations!$A$1:$X$1441,23,0) -> 0.14164549
A21: 12 | B21: =Permutations!I13 -> p1 - i1:i2 | C21: =Permutations!J13 -> p5 - i2:i4 | D21: =Permutations!K13 -> p14 - i4:i6 | E21: =Permutations!L13 -> p151 - i6:i5 | F21: =Permutations!M13 -> p61 - i5:i3 | G21: =VLOOKUP(B21,Vlookup!$A$1:$B$30,2,0) -> 1.6373343 | H21: =VLOOKUP(C21,Vlookup!$A$1:$B$30,2,0) -> 0.91082405 | I21: =VLOOKUP(D21,Vlookup!$A$1:$B$30,2,0) -> 1.4782759 | J21: =VLOOKUP(E21,Vlookup!$A$1:$B$30,2,0) -> 1.2266517 | K21: =VLOOKUP(F21,Vlookup!$A$1:$B$30,2,0) -> 1.9746367 | L21: =G21*H21*I21*J21*K21 -> 5.3399334 | M21: =H21*I21*J21*K21 -> 3.2613581 | N21: =I21*J21*K21 -> 3.5806675 | O21: =J21*K21 -> 2.4221916 | P21: =K21 -> 1.9746367 | Q21: 1 | R21: =SUM(L21:Q21) -> 17.578787 | S21: =VLOOKUP($A21,Rotations!$A$1:$X$1441,18,0) -> 0.30377144 | T21: =VLOOKUP($A21,Rotations!$A$1:$X$1441,19,0) -> 0.18552805 | U21: =VLOOKUP($A21,Rotations!$A$1:$X$1441,20,0) -> 0.056886745 | V21: =VLOOKUP($A21,Rotations!$A$1:$X$1441,21,0) -> 0.20369252 | W21: =VLOOKUP($A21,Rotations!$A$1:$X$1441,22,0) -> 0.11233066 | X21: =VLOOKUP($A21,Rotations!$A$1:$X$1441,23,0) -> 0.1377906
... A729: 720 | B729: =Permutations!I721 -> p151 - i6:i5 | C729: =Permutations!J721 -> p41 - i5:i4 | D729: =Permutations!K721 -> p31 - i4:i3 | E729: =Permutations!L721 -> p21 - i3:i2 | F729: =Permutations!M721 -> p11 - i2:i1 | G729: =VLOOKUP(B729,Vlookup!$A$1:$B$30,2,0) -> 1.2266517 | H729: =VLOOKUP(C729,Vlookup!$A$1:$B$30,2,0) -> 1.2540067 | I729: =VLOOKUP(D729,Vlookup!$A$1:$B$30,2,0) -> 2.23886 | J729: =VLOOKUP(E729,Vlookup!$A$1:$B$30,2,0) -> 1.5059827 | K729: =VLOOKUP(F729,Vlookup!$A$1:$B$30,2,0) -> 1.7440097 | L729: =G729*H729*I729*J729*K729 -> 9.0451743 | M729: =H729*I729*J729*K729 -> 7.3738732 | N729: =I729*J729*K729 -> 5.8802503 | O729: =J729*K729 -> 2.6264485 | P729: =K729 -> 1.7440097 | Q729: 1 | R729: =SUM(L729:Q729) -> 27.669756 | S729: =VLOOKUP($A729,Rotations!$A$1:$X$1441,18,0) -> 0.036140543 | T729: =VLOOKUP($A729,Rotations!$A$1:$X$1441,19,0) -> 0.063029458 | U729: =VLOOKUP($A729,Rotations!$A$1:$X$1441,20,0) -> 0.094921273 | V729: =VLOOKUP($A729,Rotations!$A$1:$X$1441,21,0) -> 0.21251544 | W729: =VLOOKUP($A729,Rotations!$A$1:$X$1441,22,0) -> 0.26649578 | X729: =VLOOKUP($A729,Rotations!$A$1:$X$1441,23,0) -> 0.32689751
S730: A | T730: B | U730: C | V730: D | W730: E | X730: F
S731: =AVERAGE(S10:S729) -> 0.14169146 | T731: =AVERAGE(T10:T729) -> 0.16063063 | U731: =AVERAGE(U10:U729) -> 0.17277553 | V731: =AVERAGE(V10:V729) -> 0.20300983 | W731: =AVERAGE(W10:W729) -> 0.16468822 | X731: =AVERAGE(X10:X729) -> 0.15720432 | Y731: average score
S732: =STDEV(S10:S729) -> 0.098387721 | T732: =STDEV(T10:T729) -> 0.10779912 | U732: =STDEV(U10:U729) -> 0.1166402 | V732: =STDEV(V10:V729) -> 0.13060294 | W732: =STDEV(W10:W729) -> 0.11206995 | X732: =STDEV(X10:X729) -> 0.10381082 | Y732: std dev
X733: =AVERAGE(S732:X732) -> 0.11155179 | Y733: HDM Inconsistency
S734: =S732*S732 -> 0.0096801436 | T734: =T732*T732 -> 0.01162065 | U734: =U732*U732 -> 0.013604936 | V734: =V732*V732 -> 0.017057127 | W734: =W732*W732 -> 0.012559674 | X734: =X732*X732 -> 0.010776686 | Y734: std dev squared
X735: =S734+T734+U734+V734+W734+X734 -> 0.075299217 | Y735: std dev squared summed
X736: =SQRT(X735) -> 0.27440703 | Y736: square root (of std dev squared summed) to lookup in RSV table

Sheet Rotations
C1: Raw Weights | K1: Before Normalization | R1: Normalized
C2: A | D2: B | E2: C | F2: D | G2: E | H2: F | I2: Sum | K2: A | L2: B | M2: C | N2: D | O2: E | P2: F | R2: A | S2: B | T2: C | U2: D | V2: E | W2: F | X2: Sum
A3: 1 | B3: abcdef | C3: =Rankings!L10 -> 7.9975632 | D3: =Rankings!M10 -> 4.8845023 | E3: =Rankings!N10 -> 3.5912178 | F3: =Rankings!O10 -> 2.5045741 | G3: =Rankings!P10 -> 1.3219359 | H3: =Rankings!Q10 -> 1 | I3: =Rankings!R10 -> 21.299793 | K3: =C3 -> 7.9975632 | L3: =D3 -> 4.8845023 | M3: =E3 -> 3.5912178 | N3: =F3 -> 2.5045741 | O3: =G3 -> 1.3219359 | P3: =H3 -> 1 | R3: =K3/$I3 -> 0.37547609 | S3: =L3/$I3 -> 0.22932158 | T3: =M3/$I3 -> 0.16860341 | U3: =N3/$I3 -> 0.11758678 | V3: =O3/$I3 -> 0.062063322 | W3: =P3/$I3 -> 0.046948812 | X3: =SUM(R3:W3) -> 1
C4: A | D4: B | E4: C | F4: D | G4: F | H4: E | K4: A | L4: B | M4: C | N4: D | O4: E | P4: F
A5: 2 | B5: abcdfe | C5: =Rankings!L11 -> 5.7902934 | D5: =Rankings!M11 -> 3.5364149 | E5: =Rankings!N11 -> 2.6000676 | F5: =Rankings!O11 -> 1.8133297 | G5: =Rankings!P11 -> 1.2266517 | H5: =Rankings!Q11 -> 1 | I5: =Rankings!R11 -> 15.966757 | K5: =C5 -> 5.7902934 | L5: =D5 -> 3.5364149 | M5: =E5 -> 2.6000676 | N5: =F5 -> 1.8133297 | O5: =H5 -> 1 | P5: =G5 -> 1.2266517 | R5: =K5/$I5 -> 0.3626468 | S5: =L5/$I5 -> 0.2214861 | T5: =M5/$I5 -> 0.16284256 | U5: =N5/$I5 -> 0.11356907 | V5: =O5/$I5 -> 0.062630125 | W5: =P5/$I5 -> 0.076825351 | X5: =SUM(R5:W5) -> 1
C6: A | D6: B | E6: C | F6: E | G6: D | H6: F | K6: A | L6: B | M6: C | N6: D | O6: E | P6: F
A7: 3 | B7: abcedf | C7: =Rankings!L12 -> 9.2534681 | D7: =Rankings!M12 -> 5.6515447 | E7: =Rankings!N12 -> 4.1551681 | F7: =Rankings!O12 -> 1.8537679 | G7: =Rankings!P12 -> 1.4782759 | H7: =Rankings!Q12 -> 1 | I7: =Rankings!R12 -> 23.392225 | K7: =C7 -> 9.2534681 | L7: =D7 -> 5.6515447 | M7: =E7 -> 4.1551681 | N7: =G7 -> 1.4782759 | O7: =F7 -> 1.8537679 | P7: =H7 -> 1 | R7: =K7/$I7 -> 0.3955788 | S7: =L7/$I7 -> 0.24159928 | T7: =M7/$I7 -> 0.17763031 | U7: =N7/$I7 -> 0.063195183 | V7: =O7/$I7 -> 0.079247182 | W7: =P7/$I7 -> 0.042749247 | X7: =SUM(R7:W7) -> 1
C8: A | D8: B | E8: C | F8: E | G8: F | H8: D | K8: A | L8: B | M8: C | N8: D | O8: E | P8: F
A9: 4 | B9: abcefd | C9: =Rankings!L13 -> 5.8522815 | D9: =Rankings!M13 -> 3.574274 | E9: =Rankings!N13 -> 2.6279027 | F9: =Rankings!O13 -> 1.1724006 | G9: =Rankings!P13 -> 0.88688156 | H9: =Rankings!Q13 -> 1 | I9: =Rankings!R13 -> 15.11374 | K9: =C9 -> 5.8522815 | L9: =D9 -> 3.574274 | M9: =E9 -> 2.6279027 | N9: =H9 -> 1 | O9: =F9 -> 1.1724006 | P9: =G9 -> 0.88688156 | R9: =K9/$I9 -> 0.38721596 | S9: =L9/$I9 -> 0.23649169 | T9: =M9/$I9 -> 0.17387507 | U9: =N9/$I9 -> 0.066164958 | V9: =O9/$I9 -> 0.077571837 | W9: =P9/$I9 -> 0.058680481 | X9: =SUM(R9:W9) -> 1
C10: A | D10: B | E10: C | F10: F | G10: D | H10: E | K10: A | L10: B | M10: C | N10: D | O10: E | P10: F
A11: 5 | B11: abcfde | C11: =Rankings!L14 -> 7.5384762 | D11: =Rankings!M14 -> 4.6041154 | E11: =Rankings!N14 -> 3.3850698 | F11: =Rankings!O14 -> 1.6803088 | G11: =Rankings!P14 -> 1.894626 | H11: =Rankings!Q14 -> 1 | I11: =Rankings!R14 -> 20.102596 | K11: =C11 -> 7.5384762 | L11: =D11 -> 4.6041154 | M11: =E11 -> 3.3850698 | N11: =G11 -> 1.894626 | O11: =H11 -> 1 | P11: =F11 -> 1.6803088 | R11: =K11/$I11 -> 0.37500013 | S11: =L11/$I11 -> 0.22903089 | T11: =M11/$I11 -> 0.16838968 | U11: =N11/$I11 -> 0.094247824 | V11: =O11/$I11 -> 0.049744819 | W11: =P11/$I11 -> 0.083586657 | X11: =SUM(R11:W11) -> 1
C12: A | D12: B | E12: C | F12: F | G12: E | H12: D | K12: A | L12: B | M12: C | N12: D | O12: E | P12: F
A13: 6 | B13: abcfed | C13: =Rankings!L15 -> 6.9010566 | D13: =Rankings!M15 -> 4.2148122 | E13: =Rankings!N15 -> 3.0988436 | F13: =Rankings!O15 -> 1.5382295 | G13: =Rankings!P15 -> 1.2540067 | H13: =Rankings!Q15 -> 1 | I13: =Rankings!R15 -> 18.006949 | K13: =C13 -> 6.9010566 | L13: =D13 -> 4.2148122 | M13: =E13 -> 3.0988436 | N13: =H13 -> 1 | O13: =G13 -> 1.2540067 | P13: =F13 -> 1.5382295 | R13: =K13/$I13 -> 0.38324409 | S13: =L13/$I13 -> 0.23406588 | T13: =M13/$I13 -> 0.17209154 | U13: =N13/$I13 -> 0.055534118 | V13: =O13/$I13 -> 0.069640155 | W13: =P13/$I13 -> 0.085424217 | X13: =SUM(R13:W13) -> 1
C14: A | D14: B | E14: D | F14: C | G14: E | H14: F | K14: A | L14: B | M14: C | N14: D | O14: E | P14: F
A15: 7 | B15: abdcef | C15: =Rankings!L16 -> 9.8933285 | D15: =Rankings!M16 -> 6.0423387 | E15: =Rankings!N16 -> 6.6339253 | F15: =Rankings!O16 -> 2.9630819 | G15: =Rankings!P16 -> 1.3219359 | H15: =Rankings!Q16 -> 1 | I15: =Rankings!R16 -> 27.85461 | K15: =C15 -> 9.8933285 | L15: =D15 -> 6.0423387 | M15: =F15 -> 2.9630819 | N15: =E15 -> 6.6339253 | O15: =G15 -> 1.3219359 | P15: =H15 -> 1 | R15: =K15/$I15 -> 0.35517742 | S15: =L15/$I15 -> 0.21692419 | T15: =M15/$I15 -> 0.10637671 | U15: =N15/$I15 -> 0.23816256 | V15: =O15/$I15 -> 0.047458425 | W15: =P15/$I15 -> 0.0359007 | X15: =SUM(R15:W15) -> 1
C16: A | D16: B | E16: D | F16: C | G16: F | H16: E | K16: A | L16: B | M16: C | N16: D | O16: E | P16: F
A17: 8 | B17: abdcfe | C17: =Rankings!L17 -> 8.2508479 | D17: =Rankings!M17 -> 5.0391956 | E17: =Rankings!N17 -> 5.5325676 | F17: =Rankings!O17 -> 2.4711539 | G17: =Rankings!P17 -> 1.2266517 | H17: =Rankings!Q17 -> 1 | I17: =Rankings!R17 -> 23.520417 | K17: =C17 -> 8.2508479 | L17: =D17 -> 5.0391956 | M17: =F17 -> 2.4711539 | N17: =E17 -> 5.5325676 | O17: =H17 -> 1 | P17: =G17 -> 1.2266517 | R17: =K17/$I17 -> 0.35079514 | S17: =L17/$I17 -> 0.21424772 | T17: =M17/$I17 -> 0.10506421 | U17: =N17/$I17 -> 0.23522405 | V17: =O17/$I17 -> 0.042516253 | W17: =P17/$I17 -> 0.052152636 | X17: =SUM(R17:W17) -> 1
C18: A | D18: B | E18: D | F18: E | G18: C | H18: F | K18: A | L18: B | M18: C | N18: D | O18: E | P18: F
A19: 9 | B19: abdecf | C19: =Rankings!L18 -> 11.239864 | D19: =Rankings!M18 -> 6.8647339 | E19: =Rankings!N18 -> 7.5368387 | F19: =Rankings!O18 -> 3.9780088 | G19: =Rankings!P18 -> 2.0145522 | H19: =Rankings!Q18 -> 1 | I19: =Rankings!R18 -> 32.633998 | K19: =C19 -> 11.239864 | L19: =D19 -> 6.8647339 | M19: =G19 -> 2.0145522 | N19: =E19 -> 7.5368387 | O19: =F19 -> 3.9780088 | P19: =H19 -> 1 | R19: =K19/$I19 -> 0.34442192 | S19: =L19/$I19 -> 0.21035528 | T19: =M19/$I19 -> 0.061731701 | U19: =N19/$I19 -> 0.23095052 | V19: =O19/$I19 -> 0.12189768 | W19: =P19/$I19 -> 0.03064289 | X19: =SUM(R19:W19) -> 1
C20: A | D20: B | E20: D | F20: E | G20: F | H20: C | K20: A | L20: B | M20: C | N20: D | O20: E | P20: F
A21: 10 | B21: abdefc | C21: =Rankings!L19 -> 5.2412986 | D21: =Rankings!M19 -> 3.201117 | E21: =Rankings!N19 -> 3.5145284 | F21: =Rankings!O19 -> 1.8549985 | G21: =Rankings!P19 -> 1.4032439 | H21: =Rankings!Q19 -> 1 | I21: =Rankings!R19 -> 16.215186 | K21: =C21 -> 5.2412986 | L21: =D21 -> 3.201117 | M21: =H21 -> 1 | N21: =E21 -> 3.5145284 | O21: =F21 -> 1.8549985 | P21: =G21 -> 1.4032439 | R21: =K21/$I21 -> 0.32323394 | S21: =L21/$I21 -> 0.19741475 | T21: =M21/$I21 -> 0.061670583 | U21: =N21/$I21 -> 0.21674301 | V21: =O21/$I21 -> 0.11439884 | W21: =P21/$I21 -> 0.08653887 | X21: =SUM(R21:W21) -> 1
C22: A | D22: B | E22: D | F22: F | G22: C | H22: E | K22: A | L22: B | M22: C | N22: D | O22: E | P22: F
A23: 11 | B23: abdfce | C23: =Rankings!L20 -> 6.9341584 | D23: =Rankings!M20 -> 4.2350291 | E23: =Rankings!N20 -> 4.6496676 | F23: =Rankings!O20 -> 3.1453314 | G23: =Rankings!P20 -> 2.2414716 | H23: =Rankings!Q20 -> 1 | I23: =Rankings!R20 -> 22.205658 | K23: =C23 -> 6.9341584 | L23: =D23 -> 4.2350291 | M23: =G23 -> 2.2414716 | N23: =E23 -> 4.6496676 | O23: =H23 -> 1 | P23: =F23 -> 3.1453314 | R23: =K23/$I23 -> 0.31226989 | S23: =L23/$I23 -> 0.19071847 | T23: =M23/$I23 -> 0.10094146 | U23: =N23/$I23 -> 0.20939112 | V23: =O23/$I23 -> 0.045033567 | W23: =P23/$I23 -> 0.14164549 | X23: =SUM(R23:W23) -> 1
C24: A | D24: B | E24: D | F24: F | G24: E | H24: C | K24: A | L24: B | M24: C | N24: D | O24: E | P24: F
A25: 12 | B25: abdfec | C25: =Rankings!L21 -> 5.3399334 | D25: =Rankings!M21 -> 3.2613581 | E25: =Rankings!N21 -> 3.5806675 | F25: =Rankings!O21 -> 2.4221916 | G25: =Rankings!P21 -> 1.9746367 | H25: =Rankings!Q21 -> 1 | I25: =Rankings!R21 -> 17.578787 | K25: =C25 -> 5.3399334 | L25: =D25 -> 3.2613581 | M25: =H25 -> 1 | N25: =E25 -> 3.5806675 | O25: =G25 -> 1.9746367 | P25: =F25 -> 2.4221916 | R25: =K25/$I25 -> 0.30377144 | S25: =L25/$I25 -> 0.18552805 | T25: =M25/$I25 -> 0.056886745 | U25: =N25/$I25 -> 0.20369252 | V25: =O25/$I25 -> 0.11233066 | W25: =P25/$I25 -> 0.1377906 | X25: =SUM(R25:W25) -> 1
C26: A | D26: B | E26: E | F26: C | G26: D | H26: F | K26: A | L26: B | M26: C | N26: D | O26: E | P26: F
A27: 13 | B27: abecdf | C27: =Rankings!L22 -> 12.329945 | D27: =Rankings!M22 -> 7.5304992 | E27: =Rankings!N22 -> 4.1855311 | F27: =Rankings!O22 -> 2.1196461 | G27: =Rankings!P22 -> 1.4782759 | H27: =Rankings!Q22 -> 1 | I27: =Rankings!R22 -> 28.643897 | K27: =C27 -> 12.329945 | L27: =D27 -> 7.5304992 | M27: =F27 -> 2.1196461 | N27: =G27 -> 1.4782759 | O27: =E27 -> 4.1855311 | P27: =H27 -> 1 | R27: =K27/$I27 -> 0.43045626 | S27: =L27/$I27 -> 0.26290065 | T27: =M27/$I27 -> 0.07399992 | U27: =N27/$I27 -> 0.051608757 | V27: =O27/$I27 -> 0.14612296 | W27: =P27/$I27 -> 0.034911451 | X27: =SUM(R27:W27) -> 1
C28: A | D28: B | E28: E | F28: C | G28: F | H28: D | K28: A | L28: B | M28: C | N28: D | O28: E | P28: F
A29: 14 | B29: abecfd | C29: =Rankings!L23 -> 10.393024 | D29: =Rankings!M23 -> 6.347527 | E29: =Rankings!N23 -> 3.5280226 | F29: =Rankings!O23 -> 1.7866692 | G29: =Rankings!P23 -> 0.88688156 | H29: =Rankings!Q23 -> 1 | I29: =Rankings!R23 -> 23.942124 | K29: =C29 -> 10.393024 | L29: =D29 -> 6.347527 | M29: =F29 -> 1.7866692 | N29: =H29 -> 1 | O29: =E29 -> 3.5280226 | P29: =G29 -> 0.88688156 | R29: =K29/$I29 -> 0.43408946 | S29: =L29/$I29 -> 0.26511963 | T29: =M29/$I29 -> 0.074624506 | U29: =N29/$I29 -> 0.041767388 | V29: =O29/$I29 -> 0.14735629 | W29: =P29/$I29 -> 0.037042727 | X29: =SUM(R29:W29) -> 1
C30: A | D30: B | E30: E | F30: D | G30: C | H30: F | K30: A | L30: B | M30: C | N30: D | O30: E | P30: F
A31: 15 | B31: abedcf | C31: =Rankings!L24 -> 16.661568 | D31: =Rankings!M24 -> 10.176033 | E31: =Rankings!N24 -> 5.6559467 | F31: =Rankings!O24 -> 4.5103002 | G31: =Rankings!P24 -> 2.0145522 | H31: =Rankings!Q24 -> 1 | I31: =Rankings!R24 -> 40.0184 | K31: =C31 -> 16.661568 | L31: =D31 -> 10.176033 | M31: =G31 -> 2.0145522 | N31: =F31 -> 4.5103002 | O31: =E31 -> 5.6559467 | P31: =H31 -> 1 | R31: =K31/$I31 -> 0.41634768 | S31: =L31/$I31 -> 0.25428385 | T31: =M31/$I31 -> 0.050340648 | U31: =N31/$I31 -> 0.11270566 | V31: =O31/$I31 -> 0.14133365 | W31: =P31/$I31 -> 0.024988505 | X31: =SUM(R31:W31) -> 1
C32: A | D32: B | E32: E | F32: D | G32: F | H32: C | K32: A | L32: B | M32: C | N32: D | O32: E | P32: F
A33: 16 | B33: abedfc | C33: =Rankings!L25 -> 7.6630045 | D33: =Rankings!M25 -> 4.6801709 | E33: =Rankings!N25 -> 2.6012885 | F33: =Rankings!O25 -> 2.0743817 | G33: =Rankings!P25 -> 1.4032439 | H33: =Rankings!Q25 -> 1 | I33: =Rankings!R25 -> 19.422089 | K33: =C33 -> 7.6630045 | L33: =D33 -> 4.6801709 | M33: =H33 -> 1 | N33: =F33 -> 2.0743817 | O33: =E33 -> 2.6012885 | P33: =G33 -> 1.4032439 | R33: =K33/$I33 -> 0.39455098 | S33: =L33/$I33 -> 0.24097155 | T33: =M33/$I33 -> 0.051487766 | U33: =N33/$I33 -> 0.10680528 | V33: =O33/$I33 -> 0.13393453 | W33: =P33/$I33 -> 0.072249894 | X33: =SUM(R33:W33) -> 1
C34: A | D34: B | E34: E | F34: F | G34: C | H34: D | K34: A | L34: B | M34: C | N34: D | O34: E | P34: F
A35: 17 | B35: abefcd | C35: =Rankings!L26 -> 7.8354147 | D35: =Rankings!M26 -> 4.7854703 | E35: =Rankings!N26 -> 2.659815 | F35: =Rankings!O26 -> 2.0120604 | G35: =Rankings!P26 -> 1.4338637 | H35: =Rankings!Q26 -> 1 | I35: =Rankings!R26 -> 19.726624 | K35: =C35 -> 7.8354147 | L35: =D35 -> 4.7854703 | M35: =G35 -> 1.4338637 | N35: =H35 -> 1 | O35: =E35 -> 2.659815 | P35: =F35 -> 2.0120604 | R35: =K35/$I35 -> 0.39719998 | S35: =L35/$I35 -> 0.24258942 | T35: =M35/$I35 -> 0.072686723 | U35: =N35/$I35 -> 0.050692911 | V35: =O35/$I35 -> 0.13483376 | W35: =P35/$I35 -> 0.1019972 | X35: =SUM(R35:W35) -> 1
C36: A | D36: B | E36: E | F36: F | G36: D | H36: C | K36: A | L36: B | M36: C | N36: D | O36: E | P36: F
A37: 18 | B37: abefdc | C37: =Rankings!L27 -> 7.7323859 | D37: =Rankings!M27 -> 4.7225455 | E37: =Rankings!N27 -> 2.6248407 | F37: =Rankings!O27 -> 1.9856036 | G37: =Rankings!P27 -> 2.23886 | H37: =Rankings!Q27 -> 1 | I37: =Rankings!R27 -> 20.304236 | K37: =C37 -> 7.7323859 | L37: =D37 -> 4.7225455 | M37: =H37 -> 1 | N37: =G37 -> 2.23886 | O37: =E37 -> 2.6248407 | P37: =F37 -> 1.9856036 | R37: =K37/$I37 -> 0.38082625 | S37: =L37/$I37 -> 0.23258918 | T37: =M37/$I37 -> 0.049250807 | U37: =N37/$I37 -> 0.11026566 | V37: =O37/$I37 -> 0.12927553 | W37: =P37/$I37 -> 0.097792581 | X37: =SUM(R37:W37) -> 1
C38: A | D38: B | E38: F | F38: C | G38: D | H38: E | K38: A | L38: B | M38: C | N38: D | O38: E | P38: F
A39: 19 | B39: abfcde | C39: =Rankings!L28 -> 8.3354933 | D39: =Rankings!M28 -> 5.0908927 | E39: =Rankings!N28 -> 3.8121019 | F39: =Rankings!O28 -> 2.7166353 | G39: =Rankings!P28 -> 1.894626 | H39: =Rankings!Q28 -> 1 | I39: =Rankings!R28 -> 22.849749 | K39: =C39 -> 8.3354933 | L39: =D39 -> 5.0908927 | M39: =F39 -> 2.7166353 | N39: =G39 -> 1.894626 | O39: =H39 -> 1 | P39: =E39 -> 3.8121019 | R39: =K39/$I39 -> 0.36479583 | S39: =L39/$I39 -> 0.22279862 | T39: =M39/$I39 -> 0.11889125 | U39: =N39/$I39 -> 0.082916707 | V39: =O39/$I39 -> 0.043764157 | W39: =P39/$I39 -> 0.16683343 | X39: =SUM(R39:W39) -> 1
C40: A | D40: B | E40: F | F40: C | G40: E | H40: D | K40: A | L40: B | M40: C | N40: D | O40: E | P40: F
...

Sheet RSV lookup table by #Variables
A1: Percentile | B1: 3 | C1: 4 | D1: 5 | E1: 6 | F1: 7 | G1: 8 | H1: 9 | I1: 10 | J1: 11 | K1: 12 | M1: Reference: M. S. Abbas, "Consistency Analysis for Judgement Quantification in Hierarchical Decision Model," PDXScholar, Portland State University, 2016.
A2: 0.01 | B2: 0.0001 | C2: 0.0188 | D2: 0.1495 | E2: 0.3012 | F2: 0.4249 | G2: 0.51 | H2: 0.5723 | I2: 0.617 | J2: 0.6521 | K2: 0.68
A3: 0.02 | B3: 0.0002 | C3: 0.0418 | D3: 0.1934 | E3: 0.3462 | F3: 0.462 | G3: 0.54 | H3: 0.5961 | I3: 0.6371 | J3: 0.669 | K3: 0.6945
A4: 0.03 | B4: 0.0005 | C4: 0.0596 | D4: 0.223 | E4: 0.3745 | F4: 0.4847 | G4: 0.5581 | H4: 0.6105 | I4: 0.6493 | J4: 0.6793 | K4: 0.7034
A5: 0.04 | B5: 0.0009 | C5: 0.0748 | D5: 0.246 | E5: 0.3955 | F5: 0.5012 | G5: 0.5713 | H5: 0.6211 | I5: 0.6582 | J5: 0.6868 | K5: 0.71
A6: 0.05 | B6: 0.0014 | C6: 0.0884 | D6: 0.2651 | E6: 0.4124 | F6: 0.5143 | G6: 0.5818 | H6: 0.6295 | I6: 0.6653 | J6: 0.6928 | K6: 0.7152
A7: 0.06 | B7: 0.0021 | C7: 0.1008 | D7: 0.2816 | E7: 0.4266 | F7: 0.5253 | G7: 0.5904 | H7: 0.6365 | I7: 0.6712 | J7: 0.6978 | K7: 0.7196
A8: 0.07 | B8: 0.0028 | C8: 0.1124 | D8: 0.2963 | E8: 0.439 | F8: 0.5347 | G8: 0.5979 | H8: 0.6425 | I8: 0.6763 | J8: 0.7022 | K8: 0.7234
A9: 0.08 | B9: 0.0037 | C9: 0.1233 | D9: 0.3095 | E9: 0.4499 | F9: 0.543 | G9: 0.6045 | H9: 0.6478 | I9: 0.6807 | J9: 0.706 | K9: 0.7267
A10: 0.09 | B10: 0.0046 | C10: 0.1337 | D10: 0.3215 | E10: 0.4597 | F10: 0.5505 | G10: 0.6104 | H10: 0.6526 | I10: 0.6848 | J10: 0.7095 | K10: 0.7298
A11: 0.1 | B11: 0.0057 | C11: 0.1437 | D11: 0.3327 | E11: 0.4686 | F11: 0.5572 | G11: 0.6157 | H11: 0.6569 | I11: 0.6884 | J11: 0.7126 | K11: 0.7325
A12: 0.11 | B12: 0.0069 | C12: 0.1532 | D12: 0.343 | E12: 0.4769 | F12: 0.5634 | G12: 0.6206 | H12: 0.6609 | I12: 0.6918 | J12: 0.7155 | K12: 0.735
A13: 0.12 | B13: 0.0083 | C13: 0.1625 | D13: 0.3528 | E13: 0.4845 | F13: 0.5691 | G13: 0.6252 | H13: 0.6646 | I13: 0.6949 | J13: 0.7182 | K13: 0.7374
... A51: 0.5 | B51: 0.1539 | C51: 0.4229 | D51: 0.5599 | E51: 0.635 | F51: 0.6814 | G51: 0.7144 | H51: 0.7384 | I51: 0.7577 | J51: 0.7729 | K51: 0.7859
